Workbook

Sheet Hoja1
A1: No | B1: Nombre | C1: Codigo
A2: 1 | B2: BOLOMBOLO [26207080] | C2: 26207080 | E2: =+_xlfn.XLOOKUP(Tabla1[[#This Row],[Codigo]],Hoja2!$D$2:$D$420,Hoja2!$C$2:$C$420) -> BOLOMBOLO [26207080;AO 01;FONDO ADAPTACION]
A3: 2 | B3: SANTA BARBARA - AUT [26185050] | C3: 26185050 | E3: =+_xlfn.XLOOKUP(Tabla1[[#This Row],[Codigo]],Hoja2!$D$2:$D$420,Hoja2!$C$2:$C$420) -> SANTA BARBARA [26185050;AO 01;FONDO ADAPTACION]
A4: 3 | B4: PARAMO BELMIRA - AUT [27015280] | C4: 27015280 | E4: =+_xlfn.XLOOKUP(Tabla1[[#This Row],[Codigo]],Hoja2!$D$2:$D$420,Hoja2!$C$2:$C$420) -> PARAMO BELMIRA [27015280;AO 01;FONDO ADAPTACION]
A5: 4 | B5: PALMIRA HACIENDA - AUT [26247010] | C5: 26247010 | E5: =+_xlfn.XLOOKUP(Tabla1[[#This Row],[Codigo]],Hoja2!$D$2:$D$420,Hoja2!$C$2:$C$420) -> HACIENDA PALMIRA [26247010;AO 01;FONDO ADAPTACION]
A6: 5 | B6: GRANJA EXPERIMENTAL EL NUS - AUT [23085080] | C6: 23085080 | E6: =+_xlfn.XLOOKUP(Tabla1[[#This Row],[Codigo]],Hoja2!$D$2:$D$420,Hoja2!$C$2:$C$420) -> GRANJA EXPERIMENTAL EL NUS [23085080;AO 01;FONDO ADAPTACION]
A7: 6 | B7: EL SIETE - AUT [11027030] | C7: 11027030 | E7: =+_xlfn.XLOOKUP(Tabla1[[#This Row],[Codigo]],Hoja2!$D$2:$D$420,Hoja2!$C$2:$C$420) -> EL SIETE [11027030; AO 01; FONDO ADAPTACION]
A8: 7 | B8: PUENTE REAL - AUT [23087150] | C8: 23087150 | E8: =+_xlfn.XLOOKUP(Tabla1[[#This Row],[Codigo]],Hoja2!$D$2:$D$420,Hoja2!$C$2:$C$420) -> C_PUENTE REAL [23087150
A9: 8 | B9: BRISAS DEL NECHI - AUT [27027060] | C9: 27027060 | E9: =+_xlfn.XLOOKUP(Tabla1[[#This Row],[Codigo]],Hoja2!$D$2:$D$420,Hoja2!$C$2:$C$420) -> BRISAS DEL NECHI [27027060;AO 01;FONDO ADAPTACION]
A10: 9 | B10: QUIBDO - AUT [11047020] | C10: 11047020 | E10: =+_xlfn.XLOOKUP(Tabla1[[#This Row],[Codigo]],Hoja2!$D$2:$D$420,Hoja2!$C$2:$C$420) -> C_QUIBDO [11047020; AO 01;FONDO ADAPTACION]
A11: 10 | B11: ANGOSTURA - AUT [2702500107] | C11: 2702500107 | E11: =+_xlfn.XLOOKUP(Tabla1[[#This Row],[Codigo]],Hoja2!$D$2:$D$420,Hoja2!$C$2:$C$420) -> ANGOSTURA - AUT [2702500107]
A12: 11 | B12: ABRIAQUI - AUT [1111500036] | C12: 1111500036 | E12: =+_xlfn.XLOOKUP(Tabla1[[#This Row],[Codigo]],Hoja2!$D$2:$D$420,Hoja2!$C$2:$C$420) -> ABRIAQUI [1111500036; AO 01;FONDO ADAPTACION]
A13: 12 | B13: LA COQUERA - AUT [26247020] | C13: 26247020 | E13: =+_xlfn.XLOOKUP(Tabla1[[#This Row],[Codigo]],Hoja2!$D$2:$D$420,Hoja2!$C$2:$C$420) -> LA COQUERA [26247020;AO 01;IDEAM]
... A154: 153 | B154: TONA - AUT [23190130] | C154: 23190130 | E154: =+_xlfn.XLOOKUP(Tabla1[[#This Row],[Codigo]],Hoja2!$D$2:$D$420,Hoja2!$C$2:$C$420) -> TONA - AUT [23190130; AO 08; MET; GPRS; FONDO ADAPTACION]
A155: 154 | B155: PIEDECUESTA GRANJA [23190700] | C155: 23190700 | E155: GRANJA PIEDECUESTA [2319500065; AO 08; MET; GPRS; FONDO ADAPTACION ]
A156: 155 | B156: SANTA ROSA - AUT [23127060] | C156: 23127060 | E156: =+_xlfn.XLOOKUP(Tabla1[[#This Row],[Codigo]],Hoja2!$D$2:$D$420,Hoja2!$C$2:$C$420) -> SANTA ROSA - AUT [23127060; SAN; HID; GOES; AO08; FONDO ADAPTACION]
A157: 156 | B157: SAN JUAN DE LOS CHORROS - AUT [2319700096] | C157: 2319700096 | E157: =+_xlfn.XLOOKUP(Tabla1[[#This Row],[Codigo]],Hoja2!$D$2:$D$420,Hoja2!$C$2:$C$420) -> SAN JUAN DE LOS CHORROS - AUT [2319700096;SAN;HID;LG;N;AO08; ]
A158: 157 | B158: AGUAS DE LA VIRGEN - AUT [16055120] | C158: 16055120 | E158: =+_xlfn.XLOOKUP(Tabla1[[#This Row],[Codigo]],Hoja2!$D$2:$D$420,Hoja2!$C$2:$C$420) -> AGUAS DE LA VIRGEN - AUT [16055120; AO 08; MET; GPRS; FONDO ADAPTACION]
A159: 158 | B159: EL TABLAZO - AUT [26015010] | C159: 26015010 | E159: =+_xlfn.XLOOKUP(Tabla1[[#This Row],[Codigo]],Hoja2!$D$2:$D$420,Hoja2!$C$2:$C$420) -> EL TABLAZO - AUT [26015010; AO 09; FONDO ADAPTACION]
A160: 159 | B160: LA DIANA - AUT [26075120] | C160: 26075120 | E160: =+_xlfn.XLOOKUP(Tabla1[[#This Row],[Codigo]],Hoja2!$D$2:$D$420,Hoja2!$C$2:$C$420) -> LA DIANA - AUT [26075120; AO 09; MET; GPRS; FONDO ADAPTACION]
A161: 160 | B161: UNIVERSIDAD DEL VALLE - AUT [26055120] | C161: 26055120 | E161: =+_xlfn.XLOOKUP(Tabla1[[#This Row],[Codigo]],Hoja2!$D$2:$D$420,Hoja2!$C$2:$C$420) -> UNIVERSIDAD DEL VALLE - AUT [26055120; AO 09; MET; GPRS; FONDO ADAPTACION]
A162: 161 | B162: SILOE - AUT [26085160] | C162: 26085160 | E162: =+_xlfn.XLOOKUP(Tabla1[[#This Row],[Codigo]],Hoja2!$D$2:$D$420,Hoja2!$C$2:$C$420) -> SILOE - AUT [26085160; AO 09; MET; GPRS; FONDO ADAPTACION]
A163: 162 | B163: BUENAVENTURA IDEAM - AUT [53119010] | C163: 53119010 | E163: =+_xlfn.XLOOKUP(Tabla1[[#This Row],[Codigo]],Hoja2!$D$2:$D$420,Hoja2!$C$2:$C$420) -> BUENAVENTURA IDEAM - AUT [53119010; VDC; HID;INMARSAT; AO09; FONDO ADAPTACION]
A164: 163 | B164: ZARAGOZA - AUT [26105250] | C164: 26105250 | E164: =+_xlfn.XLOOKUP(Tabla1[[#This Row],[Codigo]],Hoja2!$D$2:$D$420,Hoja2!$C$2:$C$420) -> ZARAGOZA - AUT [26105250; AO 09; MET; GPRS; FONDO ADAPTACION]
A165: 164 | B165: CALARCA - AUT [26125300] | C165: 26125300 | E165: =+_xlfn.XLOOKUP(Tabla1[[#This Row],[Codigo]],Hoja2!$D$2:$D$420,Hoja2!$C$2:$C$420) -> CALARCA - AUT [26125300; AO 09; MET; GPRS; FONDO ADAPTACION]
A166: 165 | B166: PIE DE PATO - AUT [55015010] | C166: 55015010 | E166: =+_xlfn.XLOOKUP(Tabla1[[#This Row],[Codigo]],Hoja2!$D$2:$D$420,Hoja2!$C$2:$C$420) -> C_PIE DE PATO - AUT [55015010; AO 09; MET; GPRS; FONDO ADAPTACION]
A167: 166 | B167: AEROPUERTO LA NUBIA AUT [26155110] | C167: 26155110 | E167: =+_xlfn.XLOOKUP(Tabla1[[#This Row],[Codigo]],Hoja2!$D$2:$D$420,Hoja2!$C$2:$C$420) -> AEROPUERTO LA NUBIA [26155110; AO 09; MET; GPRS, FONDO ADAPTACION]
... A420: 419 | B420: SARDINATA [16035030] | C420: 16035030 | E420: =+_xlfn.XLOOKUP(Tabla1[[#This Row],[Codigo]],Hoja2!$D$2:$D$420,Hoja2!$C$2:$C$420) -> SARDINATA [16035030; AO 08; MET; GPRS; FONDO ADAPTACION]

Sheet Hoja2
A1: No | B1: ID | C1: Nombre
A2: 1 | B2: 2 | C2: AGUACHICA - AUT [23195240; AO 08; MET; GPRS; FONDO ADAPTACION] | D2: 23195240 | E2: =MID(C2, SEARCH("[", C2) + 1, SEARCH(";", C2 & ";") - SEARCH("[", C2) - 1) -> 23195240
A3: 2 | B3: 3 | C3: AGUAS DE LA VIRGEN - AUT [16055120; AO 08; MET; GPRS; FONDO ADAPTACION] | D3: 16055120 | E3: =MID(C3, SEARCH("[", C3) + 1, SEARCH(";", C3 & ";") - SEARCH("[", C3) - 1) -> 16055120
A4: 3 | B4: 4 | C4: ALCALDIA DE HERRAN - AUT [16015130; NDS; MET; INMARSAT; AO08; FONDO ADAPTACION] | D4: 16015130 | E4: =MID(C4, SEARCH("[", C4) + 1, SEARCH(";", C4 & ";") - SEARCH("[", C4) - 1) -> 16015130
A5: 4 | B5: 5 | C5: ALCARAVAN AUT [37057020; ARA; HID; INMARSAT: AO08; FONDO ADAPTACION] | D5: 37057020 | E5: =MID(C5, SEARCH("[", C5) + 1, SEARCH(";", C5 & ";") - SEARCH("[", C5) - 1) -> 37057020
A6: 5 | B6: 6 | C6: ALGECIRAS - AUT [21105030; AO 04; MET; GPRS; FONDO ADAPTACION] | D6: 21105030 | E6: =MID(C6, SEARCH("[", C6) + 1, SEARCH(";", C6 & ";") - SEARCH("[", C6) - 1) -> 21105030
A7: 6 | B7: 7 | C7: ALTAQUER - AUT [51025080; AO07; FONDO ADAPTACION] | D7: 51025080 | E7: =MID(C7, SEARCH("[", C7) + 1, SEARCH(";", C7 & ";") - SEARCH("[", C7) - 1) -> 51025080
A8: 7 | B8: 9 | C8: CARAMANTA [23087160;AO 01;FONDO ADAPTACION] | D8: 23087160 | E8: =MID(C8, SEARCH("[", C8) + 1, SEARCH(";", C8 & ";") - SEARCH("[", C8) - 1) -> 23087160
A9: 8 | B9: 10 | C9: ANGOSTURA - AUT [21137050; TOL; HID; INMARSAT; AO04; FONDO ADAPTACION] | D9: 21137050 | E9: =MID(C9, SEARCH("[", C9) + 1, SEARCH(";", C9 & ";") - SEARCH("[", C9) - 1) -> 21137050
A10: 9 | B10: 11 | C10: AEROPUERTO GUAPI - AUT [53045040;AO 07;FONDO ADAPTACION] | D10: 53045040 | E10: =MID(C10, SEARCH("[", C10) + 1, SEARCH(";", C10 & ";") - SEARCH("[", C10) - 1) -> 53045040
A11: 10 | B11: 12 | C11: AQUITANIA - AUT [35095120; AO 06; MET; GPRS; FONDO ADAPTACION] | D11: 35095120 | E11: =MID(C11, SEARCH("[", C11) + 1, SEARCH(";", C11 & ";") - SEARCH("[", C11) - 1) -> 35095120
A12: 11 | B12: 13 | C12: ARAGON [27015320;AO 01;FONDO ADAPTACION] | D12: 27015320 | E12: =MID(C12, SEARCH("[", C12) + 1, SEARCH(";", C12 & ";") - SEARCH("[", C12) - 1) -> 27015320
A13: 12 | B13: 16 | C13: ARRAYANALES - AUT [26015040; AO09; IPWD; ; FNCM ] | D13: 26015040 | E13: =MID(C13, SEARCH("[", C13) + 1, SEARCH(";", C13 & ";") - SEARCH("[", C13) - 1) -> 26015040
... A369: 368 | B369: 1672 | C369: JURADO [56015040;AO 01;PROCESO DE SUSPENSIÓN] | D369: 56015040 | E369: =MID(C369, SEARCH("[", C369) + 1, SEARCH(";", C369 & ";") - SEARCH("[", C369) - 1) -> 56015040
A370: 369 | B370: 1940 | C370: CANO BARRO - AUT [13027040] | D370: 13027040] | E370: =MID(C370, SEARCH("[", C370) + 1, SEARCH(";", C370 & ";") - SEARCH("[", C370) - 1) -> 13027040]
A371: 370 | B371: 1954 | C371: RIO CHIQUITO [21057130; CAU; HID; LG; AO04; GOES: CB128186] | D371: 21057130 | E371: =MID(C371, SEARCH("[", C371) + 1, SEARCH(";", C371 & ";") - SEARCH("[", C371) - 1) -> 21057130
A372: 371 | B372: 2148 | C372: CAMPO ALEGRE [1111500203;AO 01;AUTOPISTAS AL MAR 2] | D372: 1111500203 | E372: =MID(C372, SEARCH("[", C372) + 1, SEARCH(";", C372 & ";") - SEARCH("[", C372) - 1) -> 1111500203 | F372: Codigo antiguo
A373: 372 | B373: 349 | C373: C_GRAMALOTE - AUT [1602500044; AO 08; MET; GPRS; FONDO ADAPTACION] | D373: 1602500044 | E373: =MID(C373, SEARCH("[", C373) + 1, SEARCH(";", C373 & ";") - SEARCH("[", C373) - 1) -> 1602500044 | F373: 349 | K373: 2237
A374: 373 | B374: 8 | C374: C_AEROPUERTO FURATENA - AUT [23125140; AO06; MET; FONDO ADAPTACION] | D374: 23125140 | E374: =MID(C374, SEARCH("[", C374) + 1, SEARCH(";", C374 & ";") - SEARCH("[", C374) - 1) -> 23125140 | F374: 8 | K374: 2242
A375: 374 | B375: 48 | C375: C_CHINAVITA - AUT [35075070; AO 06; MET; GPRS; FONDO ADAPTACION] | D375: 35075070 | E375: =MID(C375, SEARCH("[", C375) + 1, SEARCH(";", C375 & ";") - SEARCH("[", C375) - 1) -> 35075070 | F375: 48 | K375: 2243
A376: 375 | B376: 115 | C376: C_MURILLO - AUT [21255170; AO 10; MET; GPRS; FONDO ADAPTACION] | D376: 21255170 | E376: =MID(C376, SEARCH("[", C376) + 1, SEARCH(";", C376 & ";") - SEARCH("[", C376) - 1) -> 21255170 | F376: 115 | K376: 2244
A377: 376 | B377: 137 | C377: C_EL PEPINO - AUT [44015070;AO 07;FONDO ADAPTACION] | D377: 44015070 | E377: =MID(C377, SEARCH("[", C377) + 1, SEARCH(";", C377 & ";") - SEARCH("[", C377) - 1) -> 44015070 | F377: 137 | K377: 2246
A378: 377 | B378: 138 | C378: C_PIE DE PATO - AUT [55015010; AO 09; MET; GPRS; FONDO ADAPTACION] | D378: 55015010 | E378: =MID(C378, SEARCH("[", C378) + 1, SEARCH(";", C378 & ";") - SEARCH("[", C378) - 1) -> 55015010 | F378: 138 | K378: 2247
A379: 378 | B379: 171 | C379: C_QUIBDO [11047020; AO 01;FONDO ADAPTACION] | D379: 11047020 | E379: =MID(C379, SEARCH("[", C379) + 1, SEARCH(";", C379 & ";") - SEARCH("[", C379) - 1) -> 11047020 | F379: 171 | K379: 2248
A380: 379 | B380: 178 | C380: C_SALINAS DE UPIN - AUT [35035110;AO 03;FONDO ADAPTACION] | D380: 35035110 | E380: =MID(C380, SEARCH("[", C380) + 1, SEARCH(";", C380 & ";") - SEARCH("[", C380) - 1) -> 35035110 | F380: 178 | K380: 2249
A381: 380 | B381: 200 | C381: C_SOCHA - AUT [24035360;AO 06; MET; GPRS; FONDO ADAPTACION] | D381: 24035360 | E381: =MID(C381, SEARCH("[", C381) + 1, SEARCH(";", C381 & ";") - SEARCH("[", C381) - 1) -> 24035360 | F381: 200 | K381: 2250
A382: 381 | B382: 234 | C382: C_VIENTO LIBRE - AUT [52035040;AO 07;FONDO ADAPTACION] | D382: 52035040 | E382: =MID(C382, SEARCH("[", C382) + 1, SEARCH(";", C382 & ";") - SEARCH("[", C382) - 1) -> 52035040 | F382: 234 | K382: 2251
A383: 382 | B383: 92 | C383: C_LA JOSEFINA - AUT [52055170; AO 07;FONDO ADAPTACIÓN] | D383: 52055170 | E383: =MID(C383, SEARCH("[", C383) + 1, SEARCH(";", C383 & ";") - SEARCH("[", C383) - 1) -> 52055170 | F383: 92 | K383: 2252
A384: 383 | B384: 201 | C384: C_SOGAMOSO - AUT [24035410; AO 06; MET; GPRS; FONDO ADAPTACION] | D384: 24035410 | E384: =MID(C384, SEARCH("[", C384) + 1, SEARCH(";", C384 & ";") - SEARCH("[", C384) - 1) -> 24035410 | F384: 201 | K384: 2253
... A394: 393 | B394: 426 | C394: C_PUENTE CHACON - AUT [24017740; AO06; HID; GOES; FONDO ADAPTACION] | D394: 24017740 | E394: =MID(C394, SEARCH("[", C394) + 1, SEARCH(";", C394 & ";") - SEARCH("[", C394) - 1) -> 24017740 | F394: 426 | K394: 2316
A395: 394 | B395: 10 | C395: ANGOSTURA - AUT [2702500107] | D395: 2702500107 | E395: =MID(C395, SEARCH("[", C395) + 1, SEARCH(";", C395 & ";") - SEARCH("[", C395) - 2) -> 2702500107
A396: 395 | B396: 63 | C396: HACIENDA MANILA - AUT [21115180] | D396: 21115180 | E396: =MID(C396, SEARCH("[", C396) + 1, SEARCH(";", C396 & ";") - SEARCH("[", C396) - 2) -> 21115180
A397: 396 | B397: 228 | C397: CAÑASGORDAS - AUT [11115020] | D397: 11115020 | E397: =MID(C397, SEARCH("[", C397) + 1, SEARCH(";", C397 & ";") - SEARCH("[", C397) - 2) -> 11115020
A398: 397 | B398: 232 | C398: PUEBLO BELLO - AUT [12027010] | D398: 12027010 | E398: =MID(C398, SEARCH("[", C398) + 1, SEARCH(";", C398 & ";") - SEARCH("[", C398) - 2) -> 12027010
A399: 398 | B399: 307 | C399: EL VINCULO - AUT [26095320] | D399: 26095320 | E399: =MID(C399, SEARCH("[", C399) + 1, SEARCH(";", C399 & ";") - SEARCH("[", C399) - 2) -> 26095320
A400: 399 | B400: 317 | C400: CONEJERAS2 - AUT [26157170] | D400: 26157170 | E400: =MID(C400, SEARCH("[", C400) + 1, SEARCH(";", C400 & ";") - SEARCH("[", C400) - 2) -> 26157170
A401: 400 | B401: 341 | C401: SAN MIGUEL [2119700147] | D401: 2119700147 | E401: =MID(C401, SEARCH("[", C401) + 1, SEARCH(";", C401 & ";") - SEARCH("[", C401) - 2) -> 2119700147
A402: 401 | B402: 352 | C402: BOSQUE INTERVENIDO - AUT [35025090] | D402: 35025090 | E402: =MID(C402, SEARCH("[", C402) + 1, SEARCH(";", C402 & ";") - SEARCH("[", C402) - 2) -> 35025090
A403: 402 | B403: 354 | C403: CALOSTROS BAJO - AUT [35027510] | D403: 35027510 | E403: =MID(C403, SEARCH("[", C403) + 1, SEARCH(";", C403 & ";") - SEARCH("[", C403) - 2) -> 35027510
A404: 403 | B404: 358 | C404: QUEBRADA RINCON - AUT [35027500] | D404: 35027500 | E404: =MID(C404, SEARCH("[", C404) + 1, SEARCH(";", C404 & ";") - SEARCH("[", C404) - 2) -> 35027500
...

Sheet ajus
A1: No | B1: ID | C1: Nombre | D1: tipo | E1: cod2 | G1: nom_auto | H1: nombre_cne | I1: estado | J1: tx
A2: 1 | B2: 2 | C2: AGUACHICA - AUT [23195240; AO 08; MET; GPRS; FONDO ADAPTACION] | D2: =+_xlfn.XLOOKUP(B2,polaris!$B$2:$B$785,polaris!$D$2:$D$785) -> METEOROLÓGICA | F2: 23195240 | G2: {=+_xlfn.XLOOKUP(C2,Hoja1!$E$2:$E$420,Tabla1[Nombre])} -> AGUACHICA - AUT [23195240] | H2: =+_xlfn.XLOOKUP(F2,Tabla1[Codigo],Tabla1[Nombre]) -> AGUACHICA - AUT [23195240] | I2: =+_xlfn.XLOOKUP(F2,Hoja5!$C$2:$C$420,Hoja5!$G$2:$G$420) -> EN LINEA | J2: {=+_xlfn.XLOOKUP(F2,Hoja5!$C$2:$C$420,Hoja5!$H$2:H$420)} -> GPRS | L2: =+_xlfn.XLOOKUP(B2,polaris!$B$2:$B$785,polaris!$C$2:$C$785) -> AGUACHICA - AUT [23195240; AO 08; MET; GPRS; FONDO ADAPTACION] | M2: =+L2=C2 -> TRUE
A3: 2 | B3: 3 | C3: AGUAS DE LA VIRGEN - AUT [16055120; AO 08; MET; GPRS; FONDO ADAPTACION] | D3: =+_xlfn.XLOOKUP(B3,polaris!$B$2:$B$785,polaris!$D$2:$D$785) -> METEOROLÓGICA | F3: 16055120 | G3: {=+_xlfn.XLOOKUP(C3,Hoja1!$E$2:$E$420,Tabla1[Nombre])} -> AGUAS DE LA VIRGEN - AUT [16055120] | H3: =+_xlfn.XLOOKUP(F3,Tabla1[Codigo],Tabla1[Nombre]) -> AGUAS DE LA VIRGEN - AUT [16055120] | I3: =+_xlfn.XLOOKUP(F3,Hoja5!$C$2:$C$420,Hoja5!$G$2:$G$420) -> EN LINEA | J3: {=+_xlfn.XLOOKUP(F3,Hoja5!$C$2:$C$420,Hoja5!$H$2:H$420)} -> GPRS | L3: =+_xlfn.XLOOKUP(B3,polaris!$B$2:$B$785,polaris!$C$2:$C$785) -> AGUAS DE LA VIRGEN - AUT [16055120; AO 08; MET; GPRS; FONDO ADAPTACION] | M3: =+L3=C3 -> TRUE
A4: 3 | B4: 4 | C4: ALCALDIA DE HERRAN - AUT [16015130; NDS; MET; INMARSAT; AO08; FONDO ADAPTACION] | D4: =+_xlfn.XLOOKUP(B4,polaris!$B$2:$B$785,polaris!$D$2:$D$785) -> METEOROLÓGICA | F4: 16015130 | G4: {=+_xlfn.XLOOKUP(C4,Hoja1!$E$2:$E$420,Tabla1[Nombre])} -> ALCALDIA DE HERRAN - AUT [16015130] | H4: =+_xlfn.XLOOKUP(F4,Tabla1[Codigo],Tabla1[Nombre]) -> ALCALDIA DE HERRAN - AUT [16015130] | I4: =+_xlfn.XLOOKUP(F4,Hoja5!$C$2:$C$420,Hoja5!$G$2:$G$420) -> EN LINEA | J4: {=+_xlfn.XLOOKUP(F4,Hoja5!$C$2:$C$420,Hoja5!$H$2:H$420)} -> GPRS | L4: =+_xlfn.XLOOKUP(B4,polaris!$B$2:$B$785,polaris!$C$2:$C$785) -> ALCALDIA DE HERRAN - AUT [16015130; NDS; MET; INMARSAT; AO08; FONDO ADAPTACION] | M4: =+L4=C4 -> TRUE
A5: 4 | B5: 5 | C5: ALCARAVAN AUT [37057020; ARA; HID; INMARSAT: AO08; FONDO ADAPTACION] | D5: =+_xlfn.XLOOKUP(B5,polaris!$B$2:$B$785,polaris!$D$2:$D$785) -> HIDROLÓGICA | F5: 37057020 | G5: {=+_xlfn.XLOOKUP(C5,Hoja1!$E$2:$E$420,Tabla1[Nombre])} -> ALCARAVAN AUT [37057020] | H5: =+_xlfn.XLOOKUP(F5,Tabla1[Codigo],Tabla1[Nombre]) -> ALCARAVAN AUT [37057020] | I5: =+_xlfn.XLOOKUP(F5,Hoja5!$C$2:$C$420,Hoja5!$G$2:$G$420) -> OFFLINE MANUAL | J5: {=+_xlfn.XLOOKUP(F5,Hoja5!$C$2:$C$420,Hoja5!$H$2:H$420)} -> PROC SUSPENSION | L5: =+_xlfn.XLOOKUP(B5,polaris!$B$2:$B$785,polaris!$C$2:$C$785) -> ALCARAVAN AUT [37057020; ARA; HID; INMARSAT: AO08; FONDO ADAPTACION] | M5: =+L5=C5 -> TRUE
A6: 5 | B6: 6 | C6: ALGECIRAS - AUT [21105030; AO 04; MET; GPRS; FONDO ADAPTACION] | D6: =+_xlfn.XLOOKUP(B6,polaris!$B$2:$B$785,polaris!$D$2:$D$785) -> METEOROLÓGICA | F6: 21105030 | G6: {=+_xlfn.XLOOKUP(C6,Hoja1!$E$2:$E$420,Tabla1[Nombre])} -> ALGECIRAS - AUT [21105030] | H6: =+_xlfn.XLOOKUP(F6,Tabla1[Codigo],Tabla1[Nombre]) -> ALGECIRAS - AUT [21105030] | I6: =+_xlfn.XLOOKUP(F6,Hoja5!$C$2:$C$420,Hoja5!$G$2:$G$420) -> EN LINEA | J6: {=+_xlfn.XLOOKUP(F6,Hoja5!$C$2:$C$420,Hoja5!$H$2:H$420)} -> GPRS | L6: =+_xlfn.XLOOKUP(B6,polaris!$B$2:$B$785,polaris!$C$2:$C$785) -> ALGECIRAS - AUT [21105030; AO 04; MET; GPRS; FONDO ADAPTACION] | M6: =+L6=C6 -> TRUE
A7: 6 | B7: 7 | C7: ALTAQUER - AUT [51025080; AO07; FONDO ADAPTACION] | D7: =+_xlfn.XLOOKUP(B7,polaris!$B$2:$B$785,polaris!$D$2:$D$785) -> METEOROLÓGICA | F7: 51025080 | G7: {=+_xlfn.XLOOKUP(C7,Hoja1!$E$2:$E$420,Tabla1[Nombre])} -> ALTAQUER - AUT [51025080] | H7: =+_xlfn.XLOOKUP(F7,Tabla1[Codigo],Tabla1[Nombre]) -> ALTAQUER - AUT [51025080] | I7: =+_xlfn.XLOOKUP(F7,Hoja5!$C$2:$C$420,Hoja5!$G$2:$G$420) -> EN LINEA | J7: {=+_xlfn.XLOOKUP(F7,Hoja5!$C$2:$C$420,Hoja5!$H$2:H$420)} -> GPRS | L7: =+_xlfn.XLOOKUP(B7,polaris!$B$2:$B$785,polaris!$C$2:$C$785) -> ALTAQUER - AUT [51025080; AO07; FONDO ADAPTACION] | M7: =+L7=C7 -> TRUE
A8: 7 | B8: 9 | C8: CARAMANTA [23087160;AO 01;FONDO ADAPTACION] | D8: =+_xlfn.XLOOKUP(B8,polaris!$B$2:$B$785,polaris!$D$2:$D$785) -> HIDROLÓGICA | F8: 23087160 | G8: {=+_xlfn.XLOOKUP(C8,Hoja1!$E$2:$E$420,Tabla1[Nombre])} -> CARAMANTA - AUT [23087160] | H8: =+_xlfn.XLOOKUP(F8,Tabla1[Codigo],Tabla1[Nombre]) -> CARAMANTA - AUT [23087160] | I8: =+_xlfn.XLOOKUP(F8,Hoja5!$C$2:$C$420,Hoja5!$G$2:$G$420) -> EN LINEA | J8: {=+_xlfn.XLOOKUP(F8,Hoja5!$C$2:$C$420,Hoja5!$H$2:H$420)} -> GPRS | L8: =+_xlfn.XLOOKUP(B8,polaris!$B$2:$B$785,polaris!$C$2:$C$785) -> CARAMANTA [23087160;AO 01;FONDO ADAPTACION] | M8: =+L8=C8 -> TRUE
A9: 8 | B9: 10 | C9: ANGOSTURA - AUT [21137050; TOL; HID; INMARSAT; AO04; FONDO ADAPTACION] | D9: =+_xlfn.XLOOKUP(B9,polaris!$B$2:$B$785,polaris!$D$2:$D$785) -> HIDROLÓGICA | F9: 21137050 | G9: {=+_xlfn.XLOOKUP(C9,Hoja1!$E$2:$E$420,Tabla1[Nombre])} -> ANGOSTURA - AUT [21137050] | H9: =+_xlfn.XLOOKUP(F9,Tabla1[Codigo],Tabla1[Nombre]) -> ANGOSTURA - AUT [21137050] | I9: =+_xlfn.XLOOKUP(F9,Hoja5!$C$2:$C$420,Hoja5!$G$2:$G$420) -> DESCONECTADO | J9: {=+_xlfn.XLOOKUP(F9,Hoja5!$C$2:$C$420,Hoja5!$H$2:H$420)} -> INMARSAT | L9: =+_xlfn.XLOOKUP(B9,polaris!$B$2:$B$785,polaris!$C$2:$C$785) -> ANGOSTURA - AUT [21137050; TOL; HID; INMARSAT; AO04; FONDO ADAPTACION] | M9: =+L9=C9 -> TRUE
A10: 9 | B10: 11 | C10: AEROPUERTO GUAPI - AUT [53045040;AO 07;FONDO ADAPTACION] | D10: =+_xlfn.XLOOKUP(B10,polaris!$B$2:$B$785,polaris!$D$2:$D$785) -> METEOROLÓGICA | F10: 53045040 | G10: {=+_xlfn.XLOOKUP(C10,Hoja1!$E$2:$E$420,Tabla1[Nombre])} -> AEROPUERTO GUAPI - AUT [53045040] | H10: =+_xlfn.XLOOKUP(F10,Tabla1[Codigo],Tabla1[Nombre]) -> AEROPUERTO GUAPI - AUT [53045040] | I10: =+_xlfn.XLOOKUP(F10,Hoja5!$C$2:$C$420,Hoja5!$G$2:$G$420) -> EN LINEA | J10: {=+_xlfn.XLOOKUP(F10,Hoja5!$C$2:$C$420,Hoja5!$H$2:H$420)} -> GPRS | L10: =+_xlfn.XLOOKUP(B10,polaris!$B$2:$B$785,polaris!$C$2:$C$785) -> AEROPUERTO GUAPI - AUT [53045040;AO 07;FONDO ADAPTACION] | M10: =+L10=C10 -> TRUE
A11: 10 | B11: 12 | C11: AQUITANIA - AUT [35095120; AO 06; MET; GPRS; FONDO ADAPTACION] | D11: =+_xlfn.XLOOKUP(B11,polaris!$B$2:$B$785,polaris!$D$2:$D$785) -> METEOROLÓGICA | F11: 35095120 | G11: {=+_xlfn.XLOOKUP(C11,Hoja1!$E$2:$E$420,Tabla1[Nombre])} -> AQUITANIA - AUT [35095120] | H11: =+_xlfn.XLOOKUP(F11,Tabla1[Codigo],Tabla1[Nombre]) -> AQUITANIA - AUT [35095120] | I11: =+_xlfn.XLOOKUP(F11,Hoja5!$C$2:$C$420,Hoja5!$G$2:$G$420) -> EN LINEA | J11: {=+_xlfn.XLOOKUP(F11,Hoja5!$C$2:$C$420,Hoja5!$H$2:H$420)} -> GPRS | L11: =+_xlfn.XLOOKUP(B11,polaris!$B$2:$B$785,polaris!$C$2:$C$785) -> AQUITANIA - AUT [35095120; AO 06; MET; GPRS; FONDO ADAPTACION] | M11: =+L11=C11 -> TRUE
A12: 11 | B12: 13 | C12: ARAGON [27015320;AO 01;FONDO ADAPTACION] | D12: =+_xlfn.XLOOKUP(B12,polaris!$B$2:$B$785,polaris!$D$2:$D$785) -> METEOROLÓGICA | F12: 27015320 | G12: {=+_xlfn.XLOOKUP(C12,Hoja1!$E$2:$E$420,Tabla1[Nombre])} -> ARAGON - AUT [27015320] | H12: =+_xlfn.XLOOKUP(F12,Tabla1[Codigo],Tabla1[Nombre]) -> ARAGON - AUT [27015320] | I12: =+_xlfn.XLOOKUP(F12,Hoja5!$C$2:$C$420,Hoja5!$G$2:$G$420) -> EN LINEA | J12: {=+_xlfn.XLOOKUP(F12,Hoja5!$C$2:$C$420,Hoja5!$H$2:H$420)} -> GPRS | L12: =+_xlfn.XLOOKUP(B12,polaris!$B$2:$B$785,polaris!$C$2:$C$785) -> ARAGON [27015320;AO 01;FONDO ADAPTACION] | M12: =+L12=C12 -> TRUE
A13: 12 | B13: 16 | C13: ARRAYANALES - AUT [26015040; AO09; IPWD; ; FNCM ] | D13: =+_xlfn.XLOOKUP(B13,polaris!$B$2:$B$785,polaris!$D$2:$D$785) -> METEOROLÓGICA | F13: 26015040 | G13: {=+_xlfn.XLOOKUP(C13,Hoja1!$E$2:$E$420,Tabla1[Nombre])} -> ARRAYANALES - AUT [26015040] | H13: =+_xlfn.XLOOKUP(F13,Tabla1[Codigo],Tabla1[Nombre]) -> ARRAYANALES - AUT [26015040] | I13: =+_xlfn.XLOOKUP(F13,Hoja5!$C$2:$C$420,Hoja5!$G$2:$G$420) -> EN LINEA | J13: {=+_xlfn.XLOOKUP(F13,Hoja5!$C$2:$C$420,Hoja5!$H$2:H$420)} -> GOES | L13: =+_xlfn.XLOOKUP(B13,polaris!$B$2:$B$785,polaris!$C$2:$C$785) -> ARRAYANALES - AUT [26015040; AO09; IPWD;GOES; FNCM ] | M13: =+L13=C13 -> FALSE
... A372: 371 | B372: 2148 | C372: CAMPO ALEGRE [1111500203;AO 01;AUTOPISTAS AL MAR 2] | D372: =+_xlfn.XLOOKUP(B372,polaris!$B$2:$B$785,polaris!$D$2:$D$785) -> METEOROLÓGICA | F372: 1111500203 | G372: {=+_xlfn.XLOOKUP(C372,Hoja1!$E$2:$E$420,Tabla1[Nombre])} -> CAMPO ALEGRE [1111500203] | H372: =+_xlfn.XLOOKUP(F372,Tabla1[Codigo],Tabla1[Nombre]) -> CAMPO ALEGRE [1111500203] | I372: =+_xlfn.XLOOKUP(F372,Hoja5!$C$2:$C$420,Hoja5!$G$2:$G$420) -> EN LINEA | J372: {=+_xlfn.XLOOKUP(F372,Hoja5!$C$2:$C$420,Hoja5!$H$2:H$420)} -> GOES | L372: =+_xlfn.XLOOKUP(B372,polaris!$B$2:$B$785,polaris!$C$2:$C$785) -> CAMPO ALEGRE [1111500203;AO 01;AUTOPISTAS AL MAR 2] | M372: =+L372=C372 -> TRUE
A373: 372 | B373: 349 | C373: C_GRAMALOTE - AUT [1602500044; AO 08; MET; GPRS; FONDO ADAPTACION] | D373: =+_xlfn.XLOOKUP(E373,polaris!$B$2:$B$785,polaris!$D$2:$D$785) -> METEOROLÓGICA | E373: 2237 | F373: 1602500044 | G373: {=+_xlfn.XLOOKUP(C373,Hoja1!$E$2:$E$420,Tabla1[Nombre])} -> GRAMALOTE - AUT [1602500044] | H373: =+_xlfn.XLOOKUP(F373,Tabla1[Codigo],Tabla1[Nombre]) -> GRAMALOTE - AUT [1602500044] | I373: =+_xlfn.XLOOKUP(F373,Hoja5!$C$2:$C$420,Hoja5!$G$2:$G$420) -> EN LINEA | J373: {=+_xlfn.XLOOKUP(F373,Hoja5!$C$2:$C$420,Hoja5!$H$2:H$420)} -> GPRS | L373: =+_xlfn.XLOOKUP(E373,polaris!$B$2:$B$785,polaris!$C$2:$C$785) -> C_GRAMALOTE - AUT [1602500044; AO 08; MET; GPRS; FONDO ADAPTACION] | M373: =+L373=C373 -> TRUE
A374: 373 | B374: 8 | C374: C_AEROPUERTO FURATENA - AUT [23125140; AO06; MET; FONDO ADAPTACION] | D374: =+_xlfn.XLOOKUP(E374,polaris!$B$2:$B$785,polaris!$D$2:$D$785) -> METEOROLÓGICA | E374: 2242 | F374: 23125140 | G374: {=+_xlfn.XLOOKUP(C374,Hoja1!$E$2:$E$420,Tabla1[Nombre])} -> AEROPUERTO FURATENA - AUT [23125140] | H374: =+_xlfn.XLOOKUP(F374,Tabla1[Codigo],Tabla1[Nombre]) -> AEROPUERTO FURATENA - AUT [23125140] | I374: =+_xlfn.XLOOKUP(F374,Hoja5!$C$2:$C$420,Hoja5!$G$2:$G$420) -> EN LINEA | J374: {=+_xlfn.XLOOKUP(F374,Hoja5!$C$2:$C$420,Hoja5!$H$2:H$420)} -> GPRS | L374: =+_xlfn.XLOOKUP(E374,polaris!$B$2:$B$785,polaris!$C$2:$C$785) -> C_AEROPUERTO FURATENA - AUT [23125140; AO06; MET; FONDO ADAPTACION] | M374: =+L374=C374 -> TRUE
A375: 374 | B375: 48 | C375: C_CHINAVITA - AUT [35075070; AO 06; MET; GPRS; FONDO ADAPTACION] | D375: =+_xlfn.XLOOKUP(E375,polaris!$B$2:$B$785,polaris!$D$2:$D$785) -> METEOROLÓGICA | E375: 2243 | F375: 35075070 | G375: {=+_xlfn.XLOOKUP(C375,Hoja1!$E$2:$E$420,Tabla1[Nombre])} -> CHINAVITA - AUT [35075070] | H375: =+_xlfn.XLOOKUP(F375,Tabla1[Codigo],Tabla1[Nombre]) -> CHINAVITA - AUT [35075070] | I375: =+_xlfn.XLOOKUP(F375,Hoja5!$C$2:$C$420,Hoja5!$G$2:$G$420) -> EN LINEA | J375: {=+_xlfn.XLOOKUP(F375,Hoja5!$C$2:$C$420,Hoja5!$H$2:H$420)} -> GPRS | L375: =+_xlfn.XLOOKUP(E375,polaris!$B$2:$B$785,polaris!$C$2:$C$785) -> C_CHINAVITA - AUT [35075070; AO 06; MET; GPRS; FONDO ADAPTACION] | M375: =+L375=C375 -> TRUE
A376: 375 | B376: 115 | C376: C_MURILLO - AUT [21255170; AO 10; MET; GPRS; FONDO ADAPTACION] | D376: =+_xlfn.XLOOKUP(E376,polaris!$B$2:$B$785,polaris!$D$2:$D$785) -> METEOROLÓGICA | E376: 2244 | F376: 21255170 | G376: {=+_xlfn.XLOOKUP(C376,Hoja1!$E$2:$E$420,Tabla1[Nombre])} -> MURILLO - AUT [21255170] | H376: =+_xlfn.XLOOKUP(F376,Tabla1[Codigo],Tabla1[Nombre]) -> MURILLO - AUT [21255170] | I376: =+_xlfn.XLOOKUP(F376,Hoja5!$C$2:$C$420,Hoja5!$G$2:$G$420) -> EN LINEA | J376: {=+_xlfn.XLOOKUP(F376,Hoja5!$C$2:$C$420,Hoja5!$H$2:H$420)} -> GPRS | L376: =+_xlfn.XLOOKUP(E376,polaris!$B$2:$B$785,polaris!$C$2:$C$785) -> C_MURILLO - AUT [21255170; AO 10; MET; GPRS; FONDO ADAPTACION] | M376: =+L376=C376 -> TRUE
A377: 376 | B377: 137 | C377: C_EL PEPINO - AUT [44015070;AO 07;FONDO ADAPTACION] | D377: =+_xlfn.XLOOKUP(E377,polaris!$B$2:$B$785,polaris!$D$2:$D$785) -> METEOROLÓGICA | E377: 2246 | F377: 44015070 | G377: {=+_xlfn.XLOOKUP(C377,Hoja1!$E$2:$E$420,Tabla1[Nombre])} -> EL PEPINO - AUT [44015070] | H377: =+_xlfn.XLOOKUP(F377,Tabla1[Codigo],Tabla1[Nombre]) -> EL PEPINO - AUT [44015070] | I377: =+_xlfn.XLOOKUP(F377,Hoja5!$C$2:$C$420,Hoja5!$G$2:$G$420) -> EN LINEA | J377: {=+_xlfn.XLOOKUP(F377,Hoja5!$C$2:$C$420,Hoja5!$H$2:H$420)} -> GPRS | L377: =+_xlfn.XLOOKUP(E377,polaris!$B$2:$B$785,polaris!$C$2:$C$785) -> C_EL PEPINO - AUT [44015070;AO 07;FONDO ADAPTACION] | M377: =+L377=C377 -> TRUE
A378: 377 | B378: 138 | C378: C_PIE DE PATO - AUT [55015010; AO 09; MET; GPRS; FONDO ADAPTACION] | D378: =+_xlfn.XLOOKUP(E378,polaris!$B$2:$B$785,polaris!$D$2:$D$785) -> METEOROLÓGICA | E378: 2247 | F378: 55015010 | G378: {=+_xlfn.XLOOKUP(C378,Hoja1!$E$2:$E$420,Tabla1[Nombre])} -> PIE DE PATO - AUT [55015010] | H378: =+_xlfn.XLOOKUP(F378,Tabla1[Codigo],Tabla1[Nombre]) -> PIE DE PATO - AUT [55015010] | I378: =+_xlfn.XLOOKUP(F378,Hoja5!$C$2:$C$420,Hoja5!$G$2:$G$420) -> DESCONECTADO | J378: {=+_xlfn.XLOOKUP(F378,Hoja5!$C$2:$C$420,Hoja5!$H$2:H$420)} -> GPRS | L378: =+_xlfn.XLOOKUP(E378,polaris!$B$2:$B$785,polaris!$C$2:$C$785) -> C_PIE DE PATO - AUT [55015010; AO 09; MET; GPRS; FONDO ADAPTACION] | M378: =+L378=C378 -> TRUE
A379: 378 | B379: 171 | C379: C_QUIBDO [11047020; AO 01;FONDO ADAPTACION] | D379: =+_xlfn.XLOOKUP(E379,polaris!$B$2:$B$785,polaris!$D$2:$D$785) -> HIDROLÓGICA | E379: 2248 | F379: 11047020 | G379: {=+_xlfn.XLOOKUP(C379,Hoja1!$E$2:$E$420,Tabla1[Nombre])} -> QUIBDO - AUT [11047020] | H379: =+_xlfn.XLOOKUP(F379,Tabla1[Codigo],Tabla1[Nombre]) -> QUIBDO - AUT [11047020] | I379: =+_xlfn.XLOOKUP(F379,Hoja5!$C$2:$C$420,Hoja5!$G$2:$G$420) -> DESCONECTADO | J379: {=+_xlfn.XLOOKUP(F379,Hoja5!$C$2:$C$420,Hoja5!$H$2:H$420)} -> GPRS | L379: =+_xlfn.XLOOKUP(E379,polaris!$B$2:$B$785,polaris!$C$2:$C$785) -> C_QUIBDO [11047020; AO 01;FONDO ADAPTACION] | M379: =+L379=C379 -> TRUE
A380: 379 | B380: 178 | C380: C_SALINAS DE UPIN - AUT [35035110;AO 03;FONDO ADAPTACION] | D380: =+_xlfn.XLOOKUP(E380,polaris!$B$2:$B$785,polaris!$D$2:$D$785) -> METEOROLÓGICA | E380: 2249 | F380: 35035110 | G380: {=+_xlfn.XLOOKUP(C380,Hoja1!$E$2:$E$420,Tabla1[Nombre])} -> SALINAS DE UPIN - AUT [35035110] | H380: =+_xlfn.XLOOKUP(F380,Tabla1[Codigo],Tabla1[Nombre]) -> SALINAS DE UPIN - AUT [35035110] | I380: =+_xlfn.XLOOKUP(F380,Hoja5!$C$2:$C$420,Hoja5!$G$2:$G$420) -> EN LINEA | J380: {=+_xlfn.XLOOKUP(F380,Hoja5!$C$2:$C$420,Hoja5!$H$2:H$420)} -> GPRS | L380: =+_xlfn.XLOOKUP(E380,polaris!$B$2:$B$785,polaris!$C$2:$C$785) -> C_SALINAS DE UPIN - AUT [35035110;AO 03;FONDO ADAPTACION] | M380: =+L380=C380 -> TRUE
A381: 380 | B381: 200 | C381: C_SOCHA - AUT [24035360;AO 06; MET; GPRS; FONDO ADAPTACION] | D381: =+_xlfn.XLOOKUP(E381,polaris!$B$2:$B$785,polaris!$D$2:$D$785) -> METEOROLÓGICA | E381: 2250 | F381: 24035360 | G381: {=+_xlfn.XLOOKUP(C381,Hoja1!$E$2:$E$420,Tabla1[Nombre])} -> SOCHA - AUT [24035360] | H381: =+_xlfn.XLOOKUP(F381,Tabla1[Codigo],Tabla1[Nombre]) -> SOCHA - AUT [24035360] | I381: =+_xlfn.XLOOKUP(F381,Hoja5!$C$2:$C$420,Hoja5!$G$2:$G$420) -> EN LINEA | J381: {=+_xlfn.XLOOKUP(F381,Hoja5!$C$2:$C$420,Hoja5!$H$2:H$420)} -> GPRS | L381: =+_xlfn.XLOOKUP(E381,polaris!$B$2:$B$785,polaris!$C$2:$C$785) -> C_SOCHA - AUT [24035360;AO 06; MET; GPRS; FONDO ADAPTACION] | M381: =+L381=C381 -> TRUE
A382: 381 | B382: 234 | C382: C_VIENTO LIBRE - AUT [52035040;AO 07;FONDO ADAPTACION] | D382: =+_xlfn.XLOOKUP(E382,polaris!$B$2:$B$785,polaris!$D$2:$D$785) -> METEOROLÓGICA | E382: 2251 | F382: 52035040 | G382: {=+_xlfn.XLOOKUP(C382,Hoja1!$E$2:$E$420,Tabla1[Nombre])} -> VIENTO LIBRE - AUT [52035040] | H382: =+_xlfn.XLOOKUP(F382,Tabla1[Codigo],Tabla1[Nombre]) -> VIENTO LIBRE - AUT [52035040] | I382: =+_xlfn.XLOOKUP(F382,Hoja5!$C$2:$C$420,Hoja5!$G$2:$G$420) -> EN LINEA | J382: {=+_xlfn.XLOOKUP(F382,Hoja5!$C$2:$C$420,Hoja5!$H$2:H$420)} -> GPRS | L382: =+_xlfn.XLOOKUP(E382,polaris!$B$2:$B$785,polaris!$C$2:$C$785) -> C_VIENTO LIBRE - AUT [52035040;AO 07;FONDO ADAPTACION] | M382: =+L382=C382 -> TRUE
A383: 382 | B383: 92 | C383: C_LA JOSEFINA - AUT [52055170; AO 07;FONDO ADAPTACIÓN] | D383: =+_xlfn.XLOOKUP(E383,polaris!$B$2:$B$785,polaris!$D$2:$D$785) -> METEOROLÓGICA | E383: 2252 | F383: 52055170 | G383: {=+_xlfn.XLOOKUP(C383,Hoja1!$E$2:$E$420,Tabla1[Nombre])} -> LA JOSEFINA - AUT [52055170] | H383: =+_xlfn.XLOOKUP(F383,Tabla1[Codigo],Tabla1[Nombre]) -> LA JOSEFINA - AUT [52055170] | I383: =+_xlfn.XLOOKUP(F383,Hoja5!$C$2:$C$420,Hoja5!$G$2:$G$420) -> EN LINEA | J383: {=+_xlfn.XLOOKUP(F383,Hoja5!$C$2:$C$420,Hoja5!$H$2:H$420)} -> GPRS | L383: =+_xlfn.XLOOKUP(E383,polaris!$B$2:$B$785,polaris!$C$2:$C$785) -> C_LA JOSEFINA - AUT [52055170; AO 07;FONDO ADAPTACIÓN] | M383: =+L383=C383 -> TRUE
A384: 383 | B384: 201 | C384: C_SOGAMOSO - AUT [24035410; AO 06; MET; GPRS; FONDO ADAPTACION] | D384: =+_xlfn.XLOOKUP(E384,polaris!$B$2:$B$785,polaris!$D$2:$D$785) -> METEOROLÓGICA | E384: 2253 | F384: 24035410 | G384: {=+_xlfn.XLOOKUP(C384,Hoja1!$E$2:$E$420,Tabla1[Nombre])} -> SOGAMOSO - AUT [24035410] | H384: =+_xlfn.XLOOKUP(F384,Tabla1[Codigo],Tabla1[Nombre]) -> SOGAMOSO - AUT [24035410] | I384: =+_xlfn.XLOOKUP(F384,Hoja5!$C$2:$C$420,Hoja5!$G$2:$G$420) -> EN LINEA | J384: {=+_xlfn.XLOOKUP(F384,Hoja5!$C$2:$C$420,Hoja5!$H$2:H$420)} -> GPRS | L384: =+_xlfn.XLOOKUP(E384,polaris!$B$2:$B$785,polaris!$C$2:$C$785) -> C_SOGAMOSO - AUT [24035410; AO 06; MET; GPRS; FONDO ADAPTACION] | M384: =+L384=C384 -> TRUE
... A394: 393 | B394: 426 | C394: C_PUENTE CHACON - AUT [24017740; AO06; HID; GOES; FONDO ADAPTACION] | D394: =+_xlfn.XLOOKUP(E394,polaris!$B$2:$B$785,polaris!$D$2:$D$785) -> HIDROLÓGICA | E394: 2316 | F394: 24017740 | G394: {=+_xlfn.XLOOKUP(C394,Hoja1!$E$2:$E$420,Tabla1[Nombre])} -> PUENTE CHACON - AUT [24017740] | H394: =+_xlfn.XLOOKUP(F394,Tabla1[Codigo],Tabla1[Nombre]) -> PUENTE CHACON - AUT [24017740] | I394: =+_xlfn.XLOOKUP(F394,Hoja5!$C$2:$C$420,Hoja5!$G$2:$G$420) -> EN LINEA | J394: {=+_xlfn.XLOOKUP(F394,Hoja5!$C$2:$C$420,Hoja5!$H$2:H$420)} -> GOES | L394: =+_xlfn.XLOOKUP(E394,polaris!$B$2:$B$785,polaris!$C$2:$C$785) -> C_PUENTE CHACON - AUT [24017740; AO06; HID; GOES; FONDO ADAPTACION] | M394: =+L394=C394 -> TRUE
A395: 394 | B395: 10 | C395: ANGOSTURA - AUT [2702500107] | D395: =+_xlfn.XLOOKUP(B395,polaris!$B$2:$B$785,polaris!$D$2:$D$785) -> HIDROLÓGICA | F395: 2702500107 | G395: {=+_xlfn.XLOOKUP(C395,Hoja1!$E$2:$E$420,Tabla1[Nombre])} -> ANGOSTURA - AUT [2702500107] | H395: =+_xlfn.XLOOKUP(F395,Tabla1[Codigo],Tabla1[Nombre]) -> ANGOSTURA - AUT [2702500107] | I395: =+_xlfn.XLOOKUP(F395,Hoja5!$C$2:$C$420,Hoja5!$G$2:$G$420) -> SUSPENDIDA | J395: {=+_xlfn.XLOOKUP(F395,Hoja5!$C$2:$C$420,Hoja5!$H$2:H$420)} -> NO ESTA EN POLARIS | L395: =+_xlfn.XLOOKUP(B395,polaris!$B$2:$B$785,polaris!$C$2:$C$785) -> ANGOSTURA - AUT [21137050; TOL; HID; INMARSAT; AO04; FONDO ADAPTACION] | M395: =+L395=C395 -> FALSE
A396: 395 | B396: 63 | C396: HACIENDA MANILA - AUT [21115180] | D396: =+_xlfn.XLOOKUP(B396,polaris!$B$2:$B$785,polaris!$D$2:$D$785) -> METEOROLÓGICA | F396: 21115180 | G396: {=+_xlfn.XLOOKUP(C396,Hoja1!$E$2:$E$420,Tabla1[Nombre])} -> HACIENDA MANILA - AUT [21115180] | H396: =+_xlfn.XLOOKUP(F396,Tabla1[Codigo],Tabla1[Nombre]) -> HACIENDA MANILA - AUT [21115180] | I396: =+_xlfn.XLOOKUP(F396,Hoja5!$C$2:$C$420,Hoja5!$G$2:$G$420) -> SUSPENDIDA | J396: {=+_xlfn.XLOOKUP(F396,Hoja5!$C$2:$C$420,Hoja5!$H$2:H$420)} -> NO ESTA EN POLARIS | L396: =+_xlfn.XLOOKUP(B396,polaris!$B$2:$B$785,polaris!$C$2:$C$785) -> EL DIVISO - AUT [53075020; AO07; ORDEN PUBLICO] | M396: =+L396=C396 -> FALSE
A397: 396 | B397: 228 | C397: CAÑASGORDAS - AUT [11115020] | D397: =+_xlfn.XLOOKUP(B397,polaris!$B$2:$B$785,polaris!$D$2:$D$785) -> METEOROLÓGICA | F397: 11115020 | G397: {=+_xlfn.XLOOKUP(C397,Hoja1!$E$2:$E$420,Tabla1[Nombre])} -> CAÑASGORDAS - AUT [11115020] | H397: =+_xlfn.XLOOKUP(F397,Tabla1[Codigo],Tabla1[Nombre]) -> CAÑASGORDAS - AUT [11115020] | I397: =+_xlfn.XLOOKUP(F397,Hoja5!$C$2:$C$420,Hoja5!$G$2:$G$420) -> SUSPENDIDA | J397: {=+_xlfn.XLOOKUP(F397,Hoja5!$C$2:$C$420,Hoja5!$H$2:H$420)} -> NO ESTA EN POLARIS | L397: =+_xlfn.XLOOKUP(B397,polaris!$B$2:$B$785,polaris!$C$2:$C$785) -> UNIVERSIDAD NACIONAL [21205012; AO 11; FONDO ADAPTACION] | M397: =+L397=C397 -> FALSE
A398: 397 | B398: 232 | C398: PUEBLO BELLO - AUT [12027010] | D398: =+_xlfn.XLOOKUP(B398,polaris!$B$2:$B$785,polaris!$D$2:$D$785) -> HIDROLÓGICA | F398: 12027010 | G398: {=+_xlfn.XLOOKUP(C398,Hoja1!$E$2:$E$420,Tabla1[Nombre])} -> PUEBLO BELLO - AUT [12027010] | H398: =+_xlfn.XLOOKUP(F398,Tabla1[Codigo],Tabla1[Nombre]) -> PUEBLO BELLO - AUT [12027010] | I398: =+_xlfn.XLOOKUP(F398,Hoja5!$C$2:$C$420,Hoja5!$G$2:$G$420) -> SUSPENDIDA | J398: {=+_xlfn.XLOOKUP(F398,Hoja5!$C$2:$C$420,Hoja5!$H$2:H$420)} -> NO ESTA EN POLARIS | L398: =+_xlfn.XLOOKUP(B398,polaris!$B$2:$B$785,polaris!$C$2:$C$785) -> LA FONDA - AUT [52017030; AO-07; HID; GPRS; FONDO ADAPTACION] | M398: =+L398=C398 -> FALSE
A399: 398 | B399: 307 | C399: EL VINCULO - AUT [26095320] | D399: =+_xlfn.XLOOKUP(B399,polaris!$B$2:$B$785,polaris!$D$2:$D$785) -> HIDROLÓGICA | F399: 26095320 | G399: {=+_xlfn.XLOOKUP(C399,Hoja1!$E$2:$E$420,Tabla1[Nombre])} -> EL VINCULO - AUT [26095320] | H399: =+_xlfn.XLOOKUP(F399,Tabla1[Codigo],Tabla1[Nombre]) -> EL VINCULO - AUT [26095320] | I399: =+_xlfn.XLOOKUP(F399,Hoja5!$C$2:$C$420,Hoja5!$G$2:$G$420) -> SUSPENDIDA | J399: {=+_xlfn.XLOOKUP(F399,Hoja5!$C$2:$C$420,Hoja5!$H$2:H$420)} -> NO ESTA EN POLARIS | L399: =+_xlfn.XLOOKUP(B399,polaris!$B$2:$B$785,polaris!$C$2:$C$785) -> PALMARIGUANI - AUT [28047050; MAG; HID; INMARSAT; AO05; FONDO ADAPTACION] | M399: =+L399=C399 -> FALSE
A400: 399 | B400: 317 | C400: CONEJERAS2 - AUT [26157170] | D400: =+_xlfn.XLOOKUP(B400,polaris!$B$2:$B$785,polaris!$D$2:$D$785) -> HIDROLÓGICA | F400: 26157170 | G400: {=+_xlfn.XLOOKUP(C400,Hoja1!$E$2:$E$420,Tabla1[Nombre])} -> CONEJERAS2 - AUT [26157170] | H400: =+_xlfn.XLOOKUP(F400,Tabla1[Codigo],Tabla1[Nombre]) -> CONEJERAS2 - AUT [26157170] | I400: =+_xlfn.XLOOKUP(F400,Hoja5!$C$2:$C$420,Hoja5!$G$2:$G$420) -> SUSPENDIDA | J400: {=+_xlfn.XLOOKUP(F400,Hoja5!$C$2:$C$420,Hoja5!$H$2:H$420)} -> NO ESTA EN POLARIS | L400: =+_xlfn.XLOOKUP(B400,polaris!$B$2:$B$785,polaris!$C$2:$C$785) -> PUERTO RICO HACIENDA - AUT [29067060; MAG; HID; GPRS; AO05; FONDO ADAPTACION] | M400: =+L400=C400 -> FALSE
A401: 400 | B401: 1159 | C401: SAN MIGUEL [2119700147] | D401: =+_xlfn.XLOOKUP(B401,polaris!$B$2:$B$785,polaris!$D$2:$D$785) -> HIDROLÓGICA | F401: 2119700147 | G401: {=+_xlfn.XLOOKUP(C401,Hoja1!$E$2:$E$420,Tabla1[Nombre])} -> SAN MIGUEL [2119700147] CAMBIO DE TECNOLOGIA | H401: =+_xlfn.XLOOKUP(F401,Tabla1[Codigo],Tabla1[Nombre]) -> SAN MIGUEL [2119700147] CAMBIO DE TECNOLOGIA | I401: =+_xlfn.XLOOKUP(F401,Hoja5!$C$2:$C$420,Hoja5!$G$2:$G$420) -> SUSPENDIDA | J401: {=+_xlfn.XLOOKUP(F401,Hoja5!$C$2:$C$420,Hoja5!$H$2:H$420)} -> NO ESTA EN POLARIS | L401: =+_xlfn.XLOOKUP(B401,polaris!$B$2:$B$785,polaris!$C$2:$C$785) -> SAN MIGUEL - AUT [23057140; ANT; HID; GOES: 15C5759A; AO10; IDEAM] | M401: =+L401=C401 -> FALSE
A402: 401 | B402: 352 | C402: BOSQUE INTERVENIDO - AUT [35025090] | D402: =+_xlfn.XLOOKUP(B402,polaris!$B$2:$B$785,polaris!$D$2:$D$785) -> METEOROLÓGICA | F402: 35025090 | G402: {=+_xlfn.XLOOKUP(C402,Hoja1!$E$2:$E$420,Tabla1[Nombre])} -> BOSQUE INTERVENIDO - AUT [35025090] | H402: =+_xlfn.XLOOKUP(F402,Tabla1[Codigo],Tabla1[Nombre]) -> BOSQUE INTERVENIDO - AUT [35025090] | I402: =+_xlfn.XLOOKUP(F402,Hoja5!$C$2:$C$420,Hoja5!$G$2:$G$420) -> SUSPENDIDA | J402: {=+_xlfn.XLOOKUP(F402,Hoja5!$C$2:$C$420,Hoja5!$H$2:H$420)} -> NO ESTA EN POLARIS | L402: =+_xlfn.XLOOKUP(B402,polaris!$B$2:$B$785,polaris!$C$2:$C$785) -> ARBOLEDAS - AUT [1602500110; AO 08; MET; GPRS; FONDO ADAPTACION ] | M402: =+L402=C402 -> FALSE
A403: 402 | B403: 354 | C403: CALOSTROS BAJO - AUT [35027510] | D403: =+_xlfn.XLOOKUP(B403,polaris!$B$2:$B$785,polaris!$D$2:$D$785) -> METEOROLÓGICA | F403: 35027510 | G403: {=+_xlfn.XLOOKUP(C403,Hoja1!$E$2:$E$420,Tabla1[Nombre])} -> CALOSTROS BAJO - AUT [35027510] | H403: =+_xlfn.XLOOKUP(F403,Tabla1[Codigo],Tabla1[Nombre]) -> CALOSTROS BAJO - AUT [35027510] | I403: =+_xlfn.XLOOKUP(F403,Hoja5!$C$2:$C$420,Hoja5!$G$2:$G$420) -> SUSPENDIDA | J403: {=+_xlfn.XLOOKUP(F403,Hoja5!$C$2:$C$420,Hoja5!$H$2:H$420)} -> NO ESTA EN POLARIS | L403: =+_xlfn.XLOOKUP(B403,polaris!$B$2:$B$785,polaris!$C$2:$C$785) -> CHINACOTA - AUT [3701500114; AO 08; MET; GPRS; FONDO ADAPTACION] | M403: =+L403=C403 -> FALSE
A404: 403 | B404: 358 | C404: QUEBRADA RINCON - AUT [35027500] | D404: =+_xlfn.XLOOKUP(B404,polaris!$B$2:$B$785,polaris!$D$2:$D$785) -> METEOROLÓGICA | F404: 35027500 | G404: {=+_xlfn.XLOOKUP(C404,Hoja1!$E$2:$E$420,Tabla1[Nombre])} -> QUEBRADA RINCON - AUT [35027500] | H404: =+_xlfn.XLOOKUP(F404,Tabla1[Codigo],Tabla1[Nombre]) -> QUEBRADA RINCON - AUT [35027500] | I404: =+_xlfn.XLOOKUP(F404,Hoja5!$C$2:$C$420,Hoja5!$G$2:$G$420) -> SUSPENDIDA | J404: {=+_xlfn.XLOOKUP(F404,Hoja5!$C$2:$C$420,Hoja5!$H$2:H$420)} -> NO ESTA EN POLARIS | L404: =+_xlfn.XLOOKUP(B404,polaris!$B$2:$B$785,polaris!$C$2:$C$785) -> POLIDEPORTIVO CACHIRA - AUT [2319500125; AO 08; MET; GPRS; FONTO ADAPTACION] | M404: =+L404=C404 -> FALSE
A405: 404 | B405: 364 | C405: LAS CAMELIAS - AUT [26247050] | D405: =+_xlfn.XLOOKUP(B405,polaris!$B$2:$B$785,polaris!$D$2:$D$785) -> METEOROLÓGICA | F405: 26247050 | G405: {=+_xlfn.XLOOKUP(C405,Hoja1!$E$2:$E$420,Tabla1[Nombre])} -> LAS CAMELIAS - AUT [26247050] | H405: =+_xlfn.XLOOKUP(F405,Tabla1[Codigo],Tabla1[Nombre]) -> LAS CAMELIAS - AUT [26247050] | I405: =+_xlfn.XLOOKUP(F405,Hoja5!$C$2:$C$420,Hoja5!$G$2:$G$420) -> SUSPENDIDA | J405: {=+_xlfn.XLOOKUP(F405,Hoja5!$C$2:$C$420,Hoja5!$H$2:H$420)} -> NO ESTA EN POLARIS | L405: =+_xlfn.XLOOKUP(B405,polaris!$B$2:$B$785,polaris!$C$2:$C$785) -> PUENTE GUILLERMO - AUT [2401500052; AO 08; MET; GPRS; FONDO ADAPTACION] | M405: =+L405=C405 -> FALSE
A406: 405 | B406: 365 | C406: CAÑAFISTO [26217050] | D406: =+_xlfn.XLOOKUP(B406,polaris!$B$2:$B$785,polaris!$D$2:$D$785) -> HIDROLÓGICA | F406: 26217050 | G406: {=+_xlfn.XLOOKUP(C406,Hoja1!$E$2:$E$420,Tabla1[Nombre])} -> CAÑAFISTO [26217050] | H406: =+_xlfn.XLOOKUP(F406,Tabla1[Codigo],Tabla1[Nombre]) -> CAÑAFISTO [26217050] | I406: =+_xlfn.XLOOKUP(F406,Hoja5!$C$2:$C$420,Hoja5!$G$2:$G$420) -> SUSPENDIDA | J406: {=+_xlfn.XLOOKUP(F406,Hoja5!$C$2:$C$420,Hoja5!$H$2:H$420)} -> NO ESTA EN POLARIS | L406: =+_xlfn.XLOOKUP(B406,polaris!$B$2:$B$785,polaris!$C$2:$C$785) -> PUENTE NACIONAL - AUT [24017590; AO 08; HID; GPRS; FONDO ADAPTACION] | M406: =+L406=C406 -> FALSE
... A410: 409 | B410: 380 | C410: CHIGORODO - AUT [12015110] | D410: =+_xlfn.XLOOKUP(B410,polaris!$B$2:$B$785,polaris!$D$2:$D$785) -> METEOROLÓGICA | F410: 12015110 | G410: {=+_xlfn.XLOOKUP(C410,Hoja1!$E$2:$E$420,Tabla1[Nombre])} -> CHIGORODO - AUT [12015110] | H410: =+_xlfn.XLOOKUP(F410,Tabla1[Codigo],Tabla1[Nombre]) -> CHIGORODO - AUT [12015110] | I410: =+_xlfn.XLOOKUP(F410,Hoja5!$C$2:$C$420,Hoja5!$G$2:$G$420) -> SUSPENDIDA | J410: {=+_xlfn.XLOOKUP(F410,Hoja5!$C$2:$C$420,Hoja5!$H$2:H$420)} -> NO ESTA EN POLARIS | L410: =+_xlfn.XLOOKUP(B410,polaris!$B$2:$B$785,polaris!$C$2:$C$785) -> CINERA-VILLA OLGA [16025040; AO 08; MET; GPRS; FONDO ADAPTACION ] | M410: =+L410=C410 -> FALSE
...

Sheet Hoja5
A1: No | B1: Nombre | C1: Codigo | D1: Area Operativa | E1: Municipio | F1: Departamento | G1: Estado actual 2026 | H1: TX actual 2026 | I1: Aparece polaris | J1: Categoría | K1: Fecha de última transmisión | L1: Comentarios
A2: 1 | B2: BOLOMBOLO [26207080] | C2: 26207080 | D2: Area Operativa 01 - Antioquia-Chocó | E2: Venecia (Antioquia) | F2: Antioquia | G2: EN LINEA | H2: GPRS | I2: SI | J2: Limnigráfica
A3: 2 | B3: SANTA BARBARA - AUT [26185050] | C3: 26185050 | D3: Area Operativa 01 - Antioquia-Chocó | E3: Santa Bárbara (Antioquia) | F3: Antioquia | G3: EN LINEA | H3: GPRS | I3: SI | J3: Climática Principal
A4: 3 | B4: PARAMO BELMIRA - AUT [27015280] | C4: 27015280 | D4: Area Operativa 01 - Antioquia-Chocó | E4: Entrerrios | F4: Antioquia | G4: DESCONECTADO | H4: GPRS | I4: SI | J4: Climática Principal | K4: 20/08/2026
A5: 4 | B5: PALMIRA HACIENDA - AUT [26247010] | C5: 26247010 | D5: Area Operativa 01 - Antioquia-Chocó | E5: Cáceres | F5: Antioquia | G5: EN LINEA | H5: GOES | I5: SI | J5: Limnigráfica
A6: 5 | B6: GRANJA EXPERIMENTAL EL NUS - AUT [23085080] | C6: 23085080 | D6: Area Operativa 01 - Antioquia-Chocó | E6: San Roque | F6: Antioquia | G6: EN LINEA | H6: GPRS | I6: SI | J6: Climática Principal
A7: 6 | B7: EL SIETE - AUT [11027030] | C7: 11027030 | D7: Area Operativa 01 - Antioquia-Chocó | E7: El Carmen (Choco) | F7: Chocó | G7: EN LINEA | H7: GPRS | I7: SI | J7: Limnigráfica
A8: 7 | B8: PUENTE REAL - AUT [23087150] | C8: 23087150 | D8: Area Operativa 01 - Antioquia-Chocó | E8: Rionegro (Antioquia) | F8: Antioquia | G8: EN LINEA | H8: GPRS | I8: SI | J8: Limnigráfica
A9: 8 | B9: BRISAS DEL NECHI - AUT [27027060] | C9: 27027060 | D9: Area Operativa 01 - Antioquia-Chocó | E9: Angostura | F9: Antioquia | G9: EN LINEA | H9: GPRS | I9: SI | J9: Limnigráfica
A10: 9 | B10: QUIBDO - AUT [11047020] | C10: 11047020 | D10: Area Operativa 01 - Antioquia-Chocó | E10: Quibdó | F10: Chocó | G10: DESCONECTADO | H10: GPRS | I10: SI | J10: Limnigráfica | K10: 46119
A11: 10 | B11: ANGOSTURA - AUT [2702500107] | C11: 2702500107 | D11: Area Operativa 01 - Antioquia-Chocó | E11: Angostura | F11: Antioquia | G11: SUSPENDIDA | H11: NO ESTA EN POLARIS | I11: NO | J11: Climática Principal | K11: 45881 | L11: SUSPENDIDA CNE
A12: 11 | B12: ABRIAQUI - AUT [1111500036] | C12: 1111500036 | D12: Area Operativa 01 - Antioquia-Chocó | E12: Abriaquí | F12: Antioquia | G12: EN LINEA | H12: GPRS | I12: SI | J12: Climática Principal
A13: 12 | B13: LA COQUERA - AUT [26247020] | C13: 26247020 | D13: Area Operativa 01 - Antioquia-Chocó | E13: Caucasia | F13: Antioquia | G13: EN LINEA | H13: GPRS | I13: SI | J13: Limnigráfica
A14: 13 | B14: DABEIBA 2 - AUT [11117050] | C14: 11117050 | D14: Area Operativa 01 - Antioquia-Chocó | E14: Dabeiba | F14: Antioquia | G14: EN LINEA | H14: GPRS | I14: SI | J14: Limnigráfica
A15: 14 | B15: SANTA ISABEL VALDIVIA - AUT [26255030] | C15: 26255030 | D15: Area Operativa 01 - Antioquia-Chocó | E15: Valdivia | F15: Antioquia | G15: EN LINEA | H15: GPRS | I15: SI | J15: Agrometeorológica
A16: 15 | B16: CAMPO ALEGRE [1111500203] | C16: 1111500203 | D16: Area Operativa 01 - Antioquia-Chocó | E16: Dabeiba | F16: Antioquia | G16: EN LINEA | H16: GOES | I16: SI | J16: Climática Principal
A17: 16 | B17: LLORO [11035010] | C17: 11035010 | D17: Area Operativa 01 - Antioquia-Chocó | E17: Lloró | F17: Chocó | G17: EN LINEA | H17: GPRS | I17: SI | J17: Climática Principal
A18: 17 | B18: MACEO - AUT [23105070] | C18: 23105070 | D18: Area Operativa 01 - Antioquia-Chocó | E18: Yolombó | F18: Antioquia | G18: EN LINEA | H18: GPRS | I18: SI | J18: Climática Principal
A19: 18 | B19: SONSON [26180180] | C19: 26180180 | D19: Area Operativa 01 - Antioquia-Chocó | E19: Sonsón | F19: Antioquia | G19: EN LINEA | H19: GPRS | I19: SI | J19: Pluviográfica
A20: 19 | B20: ARAGON - AUT [27015320] | C20: 27015320 | D20: Area Operativa 01 - Antioquia-Chocó | E20: Santa Rosa De Osos | F20: Antioquia | G20: EN LINEA | H20: GPRS | I20: SI | J20: Agrometeorológica
A21: 20 | B21: MARGENTO - AUT [25027050] | C21: 25027050 | D21: Area Operativa 01 - Antioquia-Chocó | E21: Caucasia | F21: Antioquia | G21: EN LINEA | H21: GPRS | I21: SI | J21: Limnigráfica
A22: 21 | B22: SAN ANTONIO PADUA - AUT [11057020] | C22: 11057020 | D22: Area Operativa 01 - Antioquia-Chocó | E22: Vigia Del Fuerte | F22: Antioquia | G22: EN LINEA | H22: GOES | I22: SI | J22: Limnigráfica | K22: 46243
A23: 22 | B23: LA SELVA - AUT [23085260] | C23: 23085260 | D23: Area Operativa 01 - Antioquia-Chocó | E23: Rionegro (Antioquia) | F23: Antioquia | G23: EN LINEA | H23: GPRS | I23: SI | J23: Agrometeorológica
A24: 23 | B24: HACIENDA COTOVE - AUT [26225060] | C24: 26225060 | D24: Area Operativa 01 - Antioquia-Chocó | E24: Santa Fe De Antioquia | F24: Antioquia | G24: EN LINEA | H24: GPRS | I24: SI | J24: Agrometeorológica
A25: 24 | B25: METROMEDELLIN - AUT [27015310] | C25: 27015310 | D25: Area Operativa 01 - Antioquia-Chocó | E25: Bello | F25: Antioquia | G25: EN LINEA | H25: GPRS | I25: SI | J25: Climática Principal
A26: 25 | B26: LA GALERA - AUT [26217010] | C26: 26217010 | D26: Area Operativa 01 - Antioquia-Chocó | E26: Santa Fe De Antioquia | F26: Antioquia | G26: EN LINEA | H26: GPRS | I26: SI | J26: Limnigráfica | K26: 46243
A27: 26 | B27: MONTELIBANO - AUT [25017010] | C27: 25017010 | D27: Area Operativa 02 - Atlántico-Bolivar-Sucre | E27: Montelíbano | F27: Córdoba | G27: EN LINEA | H27: GPRS | I27: SI | J27: Limnimétrica
A28: 27 | B28: SAN PEDRO - AUT [25017020] | C28: 25017020 | D28: Area Operativa 02 - Atlántico-Bolivar-Sucre | E28: Puerto Libertador | F28: Córdoba | G28: EN LINEA | H28: GOES | I28: SI | J28: Limnimétrica
A29: 28 | B29: REPELON - AUT [29035200] | C29: 29035200 | D29: Area Operativa 02 - Atlántico-Bolivar-Sucre | E29: Repelón | F29: Atlantico | G29: EN LINEA | H29: GPRS | I29: SI | J29: Climática Principal
A30: 29 | B30: EL GUAMO - AUT [29015000] | C30: 29015000 | D30: Area Operativa 02 - Atlántico-Bolivar-Sucre | E30: El Guamo | F30: Bolívar | G30: EN LINEA | H30: GPRS | I30: SI | J30: Climática Ordinaria
A31: 30 | B31: MONTERIA - AUT [13067020] | C31: 13067020 | D31: Area Operativa 02 - Atlántico-Bolivar-Sucre | E31: Montería | F31: Córdoba | G31: EN LINEA | H31: GPRS | I31: SI | J31: Limnimétrica
A32: 31 | B32: PICA PICA - AUT [25017030] | C32: 25017030 | D32: Area Operativa 02 - Atlántico-Bolivar-Sucre | E32: Montelíbano | F32: Córdoba | G32: EN LINEA | H32: GOES | I32: SI | J32: Limnimétrica
A33: 32 | B33: PLANETA RICA - AUT [25025190] | C33: 25025190 | D33: Area Operativa 02 - Atlántico-Bolivar-Sucre | E33: Planeta Rica | F33: Córdoba | G33: EN LINEA | H33: GPRS | I33: SI | J33: Climática Ordinaria
A34: 33 | B34: CANO BARRO - AUT [13027040] | C34: 13027040 | D34: Area Operativa 02 - Atlántico-Bolivar-Sucre | E34: Ayapel | F34: Córdoba | G34: EN LINEA | H34: GOES | I34: SI | J34: Limnimétrica
A35: 34 | B35: REMOLINO - MAG - AUT [2904700095] | C35: 2904700095 | D35: Area Operativa 02 - Atlántico-Bolivar-Sucre | E35: Sabanagrande | F35: Atlantico | G35: EN LINEA | H35: GPRS | I35: SI | J35: Limnigráfica
A36: 35 | B36: UNIVERSIDAD UNAD CARTAGENA - AUT [1206500136] | C36: 1206500136 | D36: Area Operativa 02 - Atlántico-Bolivar-Sucre | E36: Cartagena De Indias | F36: Bolívar | G36: EN LINEA | H36: GPRS | I36: SI | J36: Climática Principal
A37: 36 | B37: SAHAGUN [25020140] | C37: 25020140 | D37: Area Operativa 02 - Atlántico-Bolivar-Sucre | E37: Sahagún | F37: Córdoba | G37: EN LINEA | H37: GPRS | I37: SI | J37: Climática Principal
A38: 37 | B38: COTOCA ABAJO - AUT [13077060] | C38: 13077060 | D38: Area Operativa 02 - Atlántico-Bolivar-Sucre | E38: Lorica | F38: Córdoba | G38: EN LINEA | H38: GPRS | I38: SI | J38: Limnimétrica
... A41: 40 | B41: NORMAL MANATI - AUT [29035080] | C41: 29035080 | D41: Area Operativa 02 - Atlántico-Bolivar-Sucre | E41: Manatí | F41: Atlantico | G41: EN LINEA | H41: GPRS | I41: SI | J41: Climática Principal
A42: 41 | B42: ESCUELA NAVAL CIOH - AUT [14019030] | C42: 14019030 | D42: Area Operativa 02 - Atlántico-Bolivar-Sucre | E42: Cartagena De Indias | F42: Bolívar | G42: OFFLINE MANUAL | H42: PROC SUSPENSION | I42: SI | J42: Mareográfica | K42: 46064
...

Sheet polaris
A1: Estado | B1: ID | C1: Estación | D1: Tipo | E1: Red | F1: Propietario | G1: Los datos más recientes
B2: 1 | C2: ACUEDUCTO MOCOA - AUT [44015060; AO07; FONDO ADAPTACION] | D2: METEOROLÓGICA | E2: 0 | F2: AO-07 | G2: 2026-09-18 07:20 | I2: =+_xlfn.XLOOKUP(B2,ajus!$B$2:$B$420,ajus!$C$2:$C$420) -> #N/A
B3: 2 | C3: AGUACHICA - AUT [23195240; AO 08; MET; GPRS; FONDO ADAPTACION] | D3: METEOROLÓGICA | E3: 0 | F3: AO-08 | G3: 2026-09-18 07:10 | I3: =+_xlfn.XLOOKUP(B3,ajus!$B$2:$B$420,ajus!$C$2:$C$420) -> AGUACHICA - AUT [23195240; AO 08; MET; GPRS; FONDO ADAPTACION]
B4: 3 | C4: AGUAS DE LA VIRGEN - AUT [16055120; AO 08; MET; GPRS; FONDO ADAPTACION] | D4: METEOROLÓGICA | E4: 0 | F4: AO-08 | G4: 2026-09-18 07:10 | I4: =+_xlfn.XLOOKUP(B4,ajus!$B$2:$B$420,ajus!$C$2:$C$420) -> AGUAS DE LA VIRGEN - AUT [16055120; AO 08; MET; GPRS; FONDO ADAPTACION]
B5: 4 | C5: ALCALDIA DE HERRAN - AUT [16015130; NDS; MET; INMARSAT; AO08; FONDO ADAPTACION] | D5: METEOROLÓGICA | E5: 0 | F5: AO-08 | G5: 2026-09-18 01:10 | I5: =+_xlfn.XLOOKUP(B5,ajus!$B$2:$B$420,ajus!$C$2:$C$420) -> ALCALDIA DE HERRAN - AUT [16015130; NDS; MET; INMARSAT; AO08; FONDO ADAPTACION]
B6: 5 | C6: ALCARAVAN AUT [37057020; ARA; HID; INMARSAT: AO08; FONDO ADAPTACION] | D6: HIDROLÓGICA | E6: 0 | F6: AO-08 | H6: SUSPENSION | I6: =+_xlfn.XLOOKUP(B6,ajus!$B$2:$B$420,ajus!$C$2:$C$420) -> ALCARAVAN AUT [37057020; ARA; HID; INMARSAT: AO08; FONDO ADAPTACION]
B7: 6 | C7: ALGECIRAS - AUT [21105030; AO 04; MET; GPRS; FONDO ADAPTACION] | D7: METEOROLÓGICA | E7: 0 | F7: AO-04 | G7: 2026-09-18 07:10 | I7: =+_xlfn.XLOOKUP(B7,ajus!$B$2:$B$420,ajus!$C$2:$C$420) -> ALGECIRAS - AUT [21105030; AO 04; MET; GPRS; FONDO ADAPTACION]
B8: 7 | C8: ALTAQUER - AUT [51025080; AO07; FONDO ADAPTACION] | D8: METEOROLÓGICA | E8: 0 | F8: AO-07 | G8: 2026-09-18 07:20 | I8: =+_xlfn.XLOOKUP(B8,ajus!$B$2:$B$420,ajus!$C$2:$C$420) -> ALTAQUER - AUT [51025080; AO07; FONDO ADAPTACION]
B9: 9 | C9: CARAMANTA [23087160;AO 01;FONDO ADAPTACION] | D9: HIDROLÓGICA | E9: 0 | F9: AO-01 | G9: 2026-09-18 06:00 | I9: =+_xlfn.XLOOKUP(B9,ajus!$B$2:$B$420,ajus!$C$2:$C$420) -> CARAMANTA [23087160;AO 01;FONDO ADAPTACION]
B10: 10 | C10: ANGOSTURA - AUT [21137050; TOL; HID; INMARSAT; AO04; FONDO ADAPTACION] | D10: HIDROLÓGICA | E10: 0 | F10: AO-04 | I10: =+_xlfn.XLOOKUP(B10,ajus!$B$2:$B$420,ajus!$C$2:$C$420) -> ANGOSTURA - AUT [21137050; TOL; HID; INMARSAT; AO04; FONDO ADAPTACION]
B11: 11 | C11: AEROPUERTO GUAPI - AUT [53045040;AO 07;FONDO ADAPTACION] | D11: METEOROLÓGICA | E11: 0 | F11: AO-07 | G11: 2026-09-18 07:10 | I11: =+_xlfn.XLOOKUP(B11,ajus!$B$2:$B$420,ajus!$C$2:$C$420) -> AEROPUERTO GUAPI - AUT [53045040;AO 07;FONDO ADAPTACION]
B12: 12 | C12: AQUITANIA - AUT [35095120; AO 06; MET; GPRS; FONDO ADAPTACION] | D12: METEOROLÓGICA | E12: 0 | F12: AO-06 | G12: 2026-09-18 07:20 | I12: =+_xlfn.XLOOKUP(B12,ajus!$B$2:$B$420,ajus!$C$2:$C$420) -> AQUITANIA - AUT [35095120; AO 06; MET; GPRS; FONDO ADAPTACION]
B13: 13 | C13: ARAGON [27015320;AO 01;FONDO ADAPTACION] | D13: METEOROLÓGICA | E13: 0 | F13: AO-01 | G13: 2026-09-18 07:10 | I13: =+_xlfn.XLOOKUP(B13,ajus!$B$2:$B$420,ajus!$C$2:$C$420) -> ARAGON [27015320;AO 01;FONDO ADAPTACION]
B14: 14 | C14: ARGELIA ANTIOQUIA [23050420; AO 01; GPRS; FONDO ADAPTACION ] | D14: METEOROLÓGICA | E14: 0 | F14: AO-01 | G14: 2026-09-18 07:10 | I14: =+_xlfn.XLOOKUP(B14,ajus!$B$2:$B$420,ajus!$C$2:$C$420) -> #N/A
B15: 16 | C15: ARRAYANALES - AUT [26015040; AO09; IPWD;GOES; FNCM ] | D15: METEOROLÓGICA | E15: 0 | F15: AO-09 | G15: 2026-09-18 06:00 | I15: =+_xlfn.XLOOKUP(B15,ajus!$B$2:$B$420,ajus!$C$2:$C$420) -> ARRAYANALES - AUT [26015040; AO09; IPWD; ; FNCM ]
B16: 18 | C16: EL BANCO - AUT [25027020; AO02; FONDO ADAPTACION] | D16: HIDROLÓGICA | E16: 0 | F16: AO-02 | G16: 2026-09-18 07:10 | I16: =+_xlfn.XLOOKUP(B16,ajus!$B$2:$B$420,ajus!$C$2:$C$420) -> #N/A
B17: 19 | C17: BARRANCABERMEJA - AUT [23157030; SAN; HID; INMARSAT; AO08; FONDO ADAPTACION] | D17: HIDROLÓGICA | E17: 0 | F17: AO-08 | H17: SUSPENSION | I17: =+_xlfn.XLOOKUP(B17,ajus!$B$2:$B$420,ajus!$C$2:$C$420) -> #N/A
B18: 20 | C18: ACAPULCO [21206280; AO11; FONDO ADAPTACION] | D18: METEOROLÓGICA | E18: 0 | F18: AO-11 | G18: 2026-09-18 07:10 | I18: =+_xlfn.XLOOKUP(B18,ajus!$B$2:$B$420,ajus!$C$2:$C$420) -> ACAPULCO [21206280; AO11; FONDO ADAPTACION]
B19: 21 | C19: BASE AEREA MARCO FIDEL SUAREZ - AUT [26085170; VDC; MET; GOES: CB1E936C; AO09; FONDO ADAPTACION] | D19: METEOROLÓGICA | E19: 0 | F19: AO-09 | G19: 2026-09-18 06:00 | I19: =+_xlfn.XLOOKUP(B19,ajus!$B$2:$B$420,ajus!$C$2:$C$420) -> BASE AEREA MARCO FIDEL SUAREZ - AUT [26085170; VDC; MET; GOES: CB1E936C; AO09; FONDO ADAPTACION]
B20: 22 | C20: BATALLON NO. 6 - AUT [29065120; AO 05; FONDO ADAPTACION] | D20: METEOROLÓGICA | E20: 0 | F20: AO-05 | G20: 2026-09-17 13:30 | I20: =+_xlfn.XLOOKUP(B20,ajus!$B$2:$B$420,ajus!$C$2:$C$420) -> BATALLON NO. 6 - AUT [29065120; AO 05; FONDO ADAPTACION]
B21: 23 | C21: BATALLON ROOKE - AUT [21215180; AO 10; MET; GPRS; FONDO ADAPTACION] | D21: METEOROLÓGICA | E21: 0 | F21: AO-10 | G21: 2026-09-18 07:10 | I21: =+_xlfn.XLOOKUP(B21,ajus!$B$2:$B$420,ajus!$C$2:$C$420) -> BATALLON ROOKE - AUT [21215180; AO 10; MET; GPRS; FONDO ADAPTACION]
B22: 24 | C22: BERLIN - AUT [37015030; AO 08; MET; GPRS; FONDO ADAPTACION] | D22: METEOROLÓGICA | E22: 0 | F22: AO-08 | G22: 2026-09-18 02:50 | I22: =+_xlfn.XLOOKUP(B22,ajus!$B$2:$B$420,ajus!$C$2:$C$420) -> BERLIN - AUT [37015030; AO 08; MET; GPRS; FONDO ADAPTACION]
B23: 25 | C23: BIOTOPO - AUT [51025060; AO07; PROCESO DE SUSPENSIÓN] | D23: METEOROLÓGICA | E23: 0 | F23: AO-07 | H23: SUSPENSION | I23: =+_xlfn.XLOOKUP(B23,ajus!$B$2:$B$420,ajus!$C$2:$C$420) -> BIOTOPO - AUT [51025060; AO07; PROCESO DE SUSPENSIÓN]
B24: 26 | C24: COLORADOS - AUT [23067020; CUN; HID; INMARSAT; AO10; FONDO ADAPTACION] | D24: HIDROLÓGICA | E24: 0 | F24: AO-10 | I24: =+_xlfn.XLOOKUP(B24,ajus!$B$2:$B$420,ajus!$C$2:$C$420) -> COLORADOS - AUT [23067020; CUN; HID; INMARSAT; AO10; FONDO ADAPTACION]
B25: 28 | C25: BOTANA - AUT [52055210; AO 07; FONDO ADAPTACION] | D25: METEOROLÓGICA | E25: 0 | F25: AO-07 | G25: 2026-09-18 07:20 | I25: =+_xlfn.XLOOKUP(B25,ajus!$B$2:$B$420,ajus!$C$2:$C$420) -> BOTANA - AUT [52055210; AO 07; FONDO ADAPTACION]
B26: 29 | C26: LA BOYERA [24015110; AO11; FONDO ADAPTACION] | D26: METEOROLÓGICA | E26: 0 | F26: AO-11 | G26: 2026-09-18 07:20 | I26: =+_xlfn.XLOOKUP(B26,ajus!$B$2:$B$420,ajus!$C$2:$C$420) -> LA BOYERA [24015110; AO11; FONDO ADAPTACION]
B27: 30 | C27: EL GUAMO - AUT [29015000; AO 02; FONDO ADAPTACION] | D27: METEOROLÓGICA | E27: 0 | F27: AO-02 | G27: 2026-09-18 07:10 | I27: =+_xlfn.XLOOKUP(B27,ajus!$B$2:$B$420,ajus!$C$2:$C$420) -> EL GUAMO - AUT [29015000; AO 02; FONDO ADAPTACION]
B28: 31 | C28: LAS BRISAS - AUT [26115090; AO 09; MET; GPRS; FONDO ADAPTACION] | D28: METEOROLÓGICA | E28: 0 | F28: AO-09 | I28: =+_xlfn.XLOOKUP(B28,ajus!$B$2:$B$420,ajus!$C$2:$C$420) -> LAS BRISAS - AUT [26115090; AO 09; MET; GPRS; FONDO ADAPTACION]
B29: 32 | C29: BUENAVENTURA IDEAM - AUT [53119010; VDC; HID;INMARSAT; AO09; FONDO ADAPTACION] | D29: HIDROLÓGICA | E29: 0 | F29: AO-09 | G29: 2026-09-18 07:10 | I29: =+_xlfn.XLOOKUP(B29,ajus!$B$2:$B$420,ajus!$C$2:$C$420) -> BUENAVENTURA IDEAM - AUT [53119010; VDC; HID;INMARSAT; AO09; FONDO ADAPTACION]
B30: 33 | C30: CERROS NOROCCIDENTALES - AUT [21215160; AO 10; MET; GPRS; FONDO ADAPTACION] | D30: METEOROLÓGICA | E30: 0 | F30: AO-10 | I30: =+_xlfn.XLOOKUP(B30,ajus!$B$2:$B$420,ajus!$C$2:$C$420) -> CERROS NOROCCIDENTALES - AUT [21215160; AO 10; MET; GPRS; FONDO ADAPTACION]
B31: 34 | C31: SAN ANTONIO PADUA [11057020; AO 01;FONDO ADAPTACION] | D31: HIDROLÓGICA | E31: 0 | F31: AO-01 | G31: 2026-09-18 06:00 | I31: =+_xlfn.XLOOKUP(B31,ajus!$B$2:$B$420,ajus!$C$2:$C$420) -> SAN ANTONIO PADUA [11057020; AO 01;FONDO ADAPTACION]
B32: 36 | C32: LA CABANA - AUT [16057030; NDS; HID; INMARSAT; AO08; FONDO ADAPTACION] | D32: HIDROLÓGICA | E32: 0 | F32: AO-08 | I32: =+_xlfn.XLOOKUP(B32,ajus!$B$2:$B$420,ajus!$C$2:$C$420) -> #N/A
B33: 37 | C33: CAJAMARCA - AUT [21215190; AO 10; MET; GPRS; FONDO ADAPTACION] | D33: METEOROLÓGICA | E33: 0 | F33: AO-10 | I33: =+_xlfn.XLOOKUP(B33,ajus!$B$2:$B$420,ajus!$C$2:$C$420) -> CAJAMARCA - AUT [21215190; AO 10; MET; GPRS; FONDO ADAPTACION]
B34: 38 | C34: CALARCA - AUT [26125300; AO 09; MET; GPRS; FONDO ADAPTACION] | D34: METEOROLÓGICA | E34: 0 | F34: AO-09 | G34: 2026-09-18 07:20 | I34: =+_xlfn.XLOOKUP(B34,ajus!$B$2:$B$420,ajus!$C$2:$C$420) -> CALARCA - AUT [26125300; AO 09; MET; GPRS; FONDO ADAPTACION]
B35: 42 | C35: LA CAPILLA - AUT [35085080; AO 06; MET; GPRS; FONDO ADAPTACION] | D35: METEOROLÓGICA | E35: 0 | F35: AO-06 | G35: 2026-09-18 07:20 | I35: =+_xlfn.XLOOKUP(B35,ajus!$B$2:$B$420,ajus!$C$2:$C$420) -> LA CAPILLA - AUT [35085080; AO 06; MET; GPRS; FONDO ADAPTACION]
B36: 43 | C36: CARMEN DE BOLIVAR - AUT [29015040; AO 02; FONDO ADAPTACION ] | D36: METEOROLÓGICA | E36: 0 | F36: AO-02 | G36: 2026-09-18 07:20 | I36: =+_xlfn.XLOOKUP(B36,ajus!$B$2:$B$420,ajus!$C$2:$C$420) -> CARMEN DE BOLIVAR - AUT [29015040; AO 02; FONDO ADAPTACION ]
B37: 44 | C37: REPELON - AUT [29035200; A0 02; FONDO ADAPTACION] | D37: METEOROLÓGICA | E37: 0 | F37: AO-02 | G37: 2026-09-18 07:10 | I37: =+_xlfn.XLOOKUP(B37,ajus!$B$2:$B$420,ajus!$C$2:$C$420) -> REPELON - AUT [29035200; A0 02; FONDO ADAPTACION]
B38: 45 | C38: CERRO PARAMO - AUT [52055150;AO 07;FONDO ADAPTACIÓN] | D38: METEOROLÓGICA | E38: 0 | F38: AO-07 | G38: 2026-09-18 07:10 | I38: =+_xlfn.XLOOKUP(B38,ajus!$B$2:$B$420,ajus!$C$2:$C$420) -> CERRO PARAMO - AUT [52055150;AO 07;FONDO ADAPTACIÓN]
B39: 47 | C39: PUENTE YOPAL - AUT [35217010; AO 06; MET; GPRS; FONDO ADAPTACION] | D39: HIDROLÓGICA | E39: 0 | F39: AO-06 | G39: 2026-09-18 07:00 | I39: =+_xlfn.XLOOKUP(B39,ajus!$B$2:$B$420,ajus!$C$2:$C$420) -> PUENTE YOPAL - AUT [35217010; AO 06; MET; GPRS; FONDO ADAPTACION]
B40: 50 | C40: ARRANCAPLUMAS - AUT [21237020; PROCESO DE SUSPENSIÓN] | D40: HIDROLÓGICA | E40: 0 | F40: AO-10 | H40: SUSPENSION | I40: =+_xlfn.XLOOKUP(B40,ajus!$B$2:$B$420,ajus!$C$2:$C$420) -> ARRANCAPLUMAS - AUT [21237020; PROCESO DE SUSPENSIÓN]
...
